"use server";
import { LoginSchema } from "@/schemas/validation";
import { z } from "zod";
import { signIn } from "@/auth";
import { DEFAULT_LOGIN_REDIRECT } from "@/routes";
import { AuthError } from "next-auth";

const login = async (values: z.infer<typeof LoginSchema>) => {
  const validatedFields = LoginSchema.safeParse(values);

  if (!validatedFields.success) {
    return {
      error: "Invalid fields",
    };
  }

  const { email, password } = validatedFields.data;

  try {
    await signIn("credentials", {
      email,
      password,
      redirectTo: DEFAULT_LOGIN_REDIRECT,
    });
  } catch (error) {
    if (error instanceof AuthError) {
      switch (error.type) {
        case "CredentialsSignin":
          return { error: "Invalid credentials" };
        default:
          console.error("An error occurred", error);
          return { error: "An error occurred" };
      }
    }

    // When using try/catch in Server Actions you should always rethrow the error otherwise it will not be redirected
    throw error;
  }
};

export { login };
